<?xml version="1.0"?>

<robot xmlns:xacro="http://www.ros.org/wiki/xacro" name="planar_4dof">

<xacro:property name="d1" value="0.5" />
<xacro:property name="d2" value="0.8" />
<xacro:property name="d3" value="1.0" />
<xacro:property name="de" value="0.5" />

<xacro:property name="file_link1" value="package://constrained_manipulation/urdf/meshes/visual/link1_v3.dae" />
<xacro:property name="file_link2" value="package://constrained_manipulation/urdf/meshes/visual/link2_v3.dae" />
<xacro:property name="file_link3" value="package://constrained_manipulation/urdf/meshes/visual/link3_v3.dae" />
<xacro:property name="file_ee" value="package://constrained_manipulation/urdf/meshes/visual/ee_v3.dae" />

<material name="gray">
    <color rgba="0.42 0.4 0.42 0.4"/>
  </material>

<material name="darkgray">
    <color rgba="0.3 0.3 0.3 0.5"/>
  </material>

  <material name="white">
    <color rgba="1 1 1 0.0"/>
  </material>

<xacro:macro name="cylinder_inertial" params="radius length mass *origin">
  <inertial>
    <mass value="${mass}" />
    <insert_block name="origin" />
    <inertia ixx="${0.0833333 * mass * (3 * radius * radius + length * length)}" ixy="0.0" ixz="0.0"
iyy="${0.0833333 * mass * (3 * radius * radius + length * length)}" iyz="0.0"
      izz="${0.5 * mass * radius * radius}" />
  </inertial>
</xacro:macro>

<xacro:macro name="revolute_joint" params="joint_name parent child pos">
  <joint name="${joint_name}" type="revolute">
    <parent link="${parent}"/>
    <child link="${child}"/>
    <origin xyz="${pos}" rpy="0 0 0"/>
    <axis xyz="0 0 1"/>
    <limit lower="-3.14159" upper="3.14159" effort="10" velocity="0.5"/>
  </joint>
</xacro:macro>

<xacro:macro name="prismatic_joint" params="joint_name parent child pos axis">
  <joint name="${joint_name}" type="prismatic">
    <parent link="${parent}"/>
    <child link="${child}"/>
    <origin xyz="${pos}" rpy="0 0 0"/>
    <axis xyz="${axis}"/>
    <limit lower="-3.0" upper="3.0" effort="10" velocity="0.5"/>
  </joint>
</xacro:macro>

<xacro:macro name="simple_link" params="title file radius length mass" >
  <link name="${title}">
    <visual>
    <geometry>
      <mesh filename="${file}"/>
    </geometry>
  </visual>
  <material name="grey">
    <color rgba="0.7 0.7 0.7 1.0"/>
  </material>
  <collision>
    <geometry>
      <mesh filename="${file}"/>
    </geometry>
  </collision>
  <xacro:cylinder_inertial radius="${radius}" length="${length}" mass="${mass}">
    <origin xyz="0.0 0.0 0.0" rpy="0 0 0" />
  </xacro:cylinder_inertial>
  </link>
</xacro:macro>


<xacro:macro name="slider_link" params="title file radius length mass" >
  <link name="${title}">
    <visual>
    <geometry>
      <!--<mesh filename="${file}"/>-->
      <box size="0.01 0.01 0.0"/>
    </geometry>
  <material name="grey">
    <color rgba="0.7 0.7 0.7 1.0"/>
  </material>
  </visual>
  <collision>
    <geometry>
      <box size="0.1 0.1 0.0"/>
    </geometry>
  </collision>
  <xacro:cylinder_inertial radius="${radius}" length="${length}" mass="${mass}">
    <origin xyz="0.0 0.0 0.0" rpy="0 0 0" />
  </xacro:cylinder_inertial>
  </link>

</xacro:macro>

<xacro:macro name="slider_link2" params="title file radius length mass" >
  <link name="${title}">
    <visual>
    <geometry>
      <!--<mesh filename="${file}"/>-->
      <cylinder length="0.02" radius="0.2"/>
    </geometry>
<material name="gray"/>
  </visual>
  <collision>
    <geometry>
      <box size="0.1 0.1 0.0"/>
    </geometry>
  </collision>
  <xacro:cylinder_inertial radius="${radius}" length="${length}" mass="${mass}">
    <origin xyz="0.0 0.0 0.0" rpy="0 0 0" />
  </xacro:cylinder_inertial>
  </link>
</xacro:macro>
<link name="world"/>


<xacro:slider_link title="L0" file="${file_link1}" radius="0.2" mass="1" length="${d3}"/>
<xacro:prismatic_joint joint_name="q0" parent="world" child="L0" pos="0.0 0.0 0.0" axis="0.0 1.0 0.0"/>

<xacro:slider_link2 title="L1" file="${file_link1}" radius="0.2" mass="1" length="${d3}"/>
<xacro:prismatic_joint joint_name="q1" parent="L0" child="L1" pos="0.0 0.0 0.0" axis="1.0 0.0 0.0"/>

<xacro:simple_link title="L2" file="${file_link2}" radius="0.2" mass="1" length="${d2}"/>
<xacro:revolute_joint joint_name="q2" parent="L1" child="L2" pos="0.0 0.0 0.0"/>

<xacro:simple_link title="EE" file="${file_ee}" radius="0.2" mass="1" length="${de}" />
<xacro:revolute_joint joint_name="q3" parent="L2" child="EE" pos="${d2} 0 0"/>


</robot>
